Workbook

Sheet 대시보드
A1: 📊 운영 대시보드
A2: 차량 부업 — Andrew | 2026 시즌
A4: 🟦 핵심 지표
A5: YTD 총 운행 km | D5: YTD 총 수입 (€)
A6: =SUM(여행_기록!C5:C55)+SUM(이동_기록!D5:D85) -> 200 | D6: =SUM(여행_기록!J5:J55)+SUM(이동_기록!H5:H85) -> 50
A8: YTD 총 진짜 비용 (€) | D8: YTD 흑자/적자 (€)
A9: =SUM(여행_기록!K5:K55)+SUM(이동_기록!I5:I85) -> 113.02333 | D9: =SUM(여행_기록!M5:M55)+SUM(이동_기록!K5:K85) -> -63.023333
A11: YTD 정비 지출 (€) | D11: 정비 충당 잔액 (€)
A12: =정비_영수증!B9 -> 0 | D12: =정비_영수증!B10 -> 항목
A14: 📐 차량 비용 모델 (실시간)
A15: 진짜 km당 실비 | D15: =차량_정보!C38 -> 0.60511667
A16: 마모/감가 km당 | D16: =차량_정보!C39 -> 0.44011667
A17: 연료 km당 | D17: =차량_정보!C28 -> 0.125
A18: 내 시간당 단가 | D18: =차량_정보!B16 -> 15
A19: 이사 노동 시간당 | D19: =차량_정보!B17 -> 20
A22: 💝 친구 보조금 누적 (Tier 1 의도된 적자)
A23: Tier 1 트립 합계 (적자 = 너의 보조금) | D23: =SUMIFS(여행_기록!M5:M55,여행_기록!I5:I55,1) -> -63.023333
A25: 🔗 빠른 이동
A26: ↳ 새 여행 기록하기 → 여행_기록 시트
A27: ↳ 새 픽업·이사 기록하기 → 이동_기록 시트
A28: ↳ 정비 영수증 입력 → 정비_영수증 시트
A29: ↳ 가격 시뮬레이션 → 가격_계산기 시트
A30: ↳ 차량 정보 변경 → 차량_정보 시트

Sheet 차량_정보
A1: 🚗 차량 정보 + km당 비용 모델
A3: ⚙️ 차량 기본 정보 (노란 셀 = 수정 가능)
A4: 차종 | B4: Citroen Grand C4 Picasso 2012
A5: 현재 주행거리 (km) | B5: 180000
A6: 차량 구매가 (€) | B6: 3750
A7: 연비 (km/L) | B7: 16
A8: 연료 가격 (€/L) | B8: 2
A9: 연 보험료 (€) | B9: 1297
A10: 연 Motor Tax (€) | B10: 280
A11: NCT (격년 → 연 평균 €) | B11: 56
A12: 연 정기 정비/소모품 충당 (€) | B12: 2500
A13: 연 큰수리 예비비 (€) | B13: 2000
A14: 잔여 차량 수명 (km) | B14: 120000
A15: 연 추정 운행 (km) | B15: 15000
A16: 내 시간당 단가 (€) | B16: 15
... A23: 부트 적재 (3열 접음, L) | B23: 1800
A26: 📊 km당 비용 모델 (자동 계산)
A27: 항목 | B27: 연 (€) | C27: km당 (€) | D27: 메모
A28: 연료 | C28: =B8/B7 -> 0.125 | D28: €2/L ÷ 16km/L = km당 연료비
A29: 톨/주차 평균 | C29: =B18 -> 0.04 | D29: 장거리 평균 추정값
A30: 보험 | B30: =B9 -> 1297 | C30: =B9/B15 -> 0.086466667
A31: Motor Tax | B31: =B10 -> 280 | C31: =B10/B15 -> 0.018666667
A32: NCT (연 평균) | B32: =B11 -> 56 | C32: =B11/B15 -> 0.0037333333 | D32: 격년 평균
A33: 정기 정비/소모품 | B33: =B12 -> 2500 | C33: =B12/B15 -> 0.16666667 | D33: 오일·타이어·브레이크 충당
A34: 큰수리 예비 | B34: =B13 -> 2000 | C34: =B13/B15 -> 0.13333333 | D34: 18만 km 디젤 — 터보·DPF·클러치 충당
A35: 감가상각 | C35: =B6/B14 -> 0.03125 | D35: 구매가 ÷ 잔여 수명
A36: ↳ 변동비 소계 | C36: =C28+C29 -> 0.165 | D36: 연료 + 톨/주차
A37: ↳ 고정·마모·감가 소계 | C37: =SUM(C30:C35) -> 0.44011667 | D37: 보험·세금·정비·큰수리·감가
A38: 🟦 진짜 km당 실비 (적자 분기점) | C38: =C36+C37 -> 0.60511667
A39: ↳ 마모/감가만 (어제 같은 트립에 사용) | C39: =C37 -> 0.44011667 | D39: 친구 보조금 계산용

Sheet 가격_가이드
A1: 💰 가격 가이드 v2 (2026-04 / IKEA Tier A 분리)
A3: 🚗 이동 모드 (네가 일하러 움직임)
A4: 서비스 | B4: 권장가 (€) | C4: Red Door 비교 | D4: 시간 (h) | E4: 메모
A5: 시내 픽업/샌딩 (D1–D8) | B5: 45 | C5: −€5 (Red Door €50) | D5: 1.25 | E5: 톨·1h 대기 포함
A6: 외곽 (D6W·D9·D15·D24) | B6: 50–55 | C6: 무경쟁 | D6: 1.5 | E6: 12km 초과분 €1.5/km
A7: Maynooth/Lucan (~25km) | B7: 65 | C7: 무경쟁 | D7: 2
A8: Bray/Greystones (~25–35km) | B8: 65–80 | C8: 무경쟁 | D8: 2
A9: Drogheda (50km) | B9: 100 | C9: 무경쟁 | D9: 2.5
A10: Wicklow Town (50km) | B10: 100 | C10: 무경쟁 | D10: 2.5
A11: 지방 (Belfast/Galway/Cork) | B11: 별도 견적 | C11: 무경쟁 | D11: 4+ | E11: km × €1.5 + 시간 × €15
A12: 야간/새벽 (22–06시) | B12: +€10 | E12: 모든 픽업 공통
A13: 공휴일 | B13: +€10
A14: 시내 짐 운송 (1h, 캐리어/박스) | B14: 40 | C14: −€5 (Red Door €45) | D14: 1
A15: IKEA Tier A — Zone 1: IKEA 0–10km (시내·D9·D15) | B15: 50 | C15: vs Man with a Van €60+ | D15: 1.5 | E15: 대표: D1–D8
A16: IKEA Tier A — Zone 2: IKEA 10–20km (D24·Tallaght·Lucan) | B16: 60 | C16: 무경쟁 | D16: 1.75
A17: IKEA Tier A — Zone 3: IKEA 20–30km (Maynooth·Bray) | B17: 75 | C17: 무경쟁 | D17: 2
A18: IKEA Tier A — Zone 4: IKEA 30–50km (Drogheda·Naas·Wicklow Town) | B18: 100 | C18: 무경쟁 | D18: 2.5
A19: IKEA Tier A — Zone 5: IKEA 50km+ | B19: 별도 견적 | C19: 무경쟁 | D19: 3+ | E19: €50 + (거리−10)×€2
A20: IKEA Tier B·C (동행 + 큰 가구) | B20: TBD | C20: 추후 | D20: — | E20: 검증 후 v3 추가
A21: 큰 장보기 (Costco/Lidl) | B21: 40 | C21: 무경쟁 | D21: 1.5
A22: 소형 이사 1bed (4h, 고객 도움) | B22: 130–150 | C22: 무경쟁 | D22: 4
A23: 소형 이사 1bed (4h, 너 단독) | B23: 180–220 | C23: 무경쟁 | D23: 4
A24: 시간 초과 | B24: +€20/h | E24: 4h 초과 시 명시
A26: 🌿 여행 모드 (km × €/km × 인원)
A27: 티어 | B27: km당 1인 (€) | C27: 4명 그룹 200km 시 1인 (€) | D27: 6명 그룹 200km 시 1인 (€) | E27: 메모
A28: 🟢 절친 (Tier 1) | B28: 0.15 | C28: =B28*200 -> 30 | D28: =B28*200 -> 30 | E28: 의도된 보조금 + 친구 모드
A29: 🟡 친구 (Tier 2) | B29: 0.2 | C29: =B29*200 -> 40 | D29: =B29*200 -> 40 | E29: 정직한 분담 + 너 흑자 약간
A30: 🟠 지인 (Tier 3) | B30: 0.25 | C30: =B30*200 -> 50 | D30: =B30*200 -> 50 | E30: 시장가, 너 흑자 60%+
A32: 📝 여행 모드 노트:
A33: • 식비·입장료·숙박 모두 별도 (각자)
A34: • 5명+ 그룹은 km당 −€0.05 할인 가능 (협의)
A35: • 합류·하차 시점이 다르면 구간별 가중 평균 적용
A36: • 가격은 1:1 카톡으로만 공유, 외부 광고 X
A38: 📝 IKEA Tier A 노트 (운송만, 1.5h):
A39: • 거리 = IKEA Ballymun → 손님 집까지의 km
A40: • Zone 1 (0–10km): D1–D8, D9, D15 대부분
A41: • Zone 2 (10–20km): D24, Tallaght, Lucan, Howth
A42: • Zone 3 (20–30km): Maynooth, Bray, Greystones
A43: • Zone 4 (30–50km): Drogheda, Naas, Wicklow Town
A44: • Zone 5 (50km+): 별도 견적 = €50 + (거리−10)×€2
...

Sheet 여행_기록
A1: 🌿 여행 기록부 — 친구·지인 1일 여행
A3: 👇 노란 셀에 입력 → 회색 셀은 자동 계산
A4: 일자 | B4: 목적지 | C4: km | D4: 시간(h) | E4: 연료(€) | F4: 톨(€) | G4: 주차(€) | H4: 인원(친구) | I4: 티어 (1/2/3) | J4: 받은 돈(€) | K4: 진짜 비용(€) | L4: 권장가 (€) | M4: 흑자/적자 (€) | N4: 메모
A5: 2026-04-26 | B5: Wicklow | C5: 200 | D5: 6 | E5: 25 | F5: 0 | G5: 0 | H5: 4 | I5: 1 | J5: 50 | K5: =IF(C5="","",IF(E5="",C5*차량_정보!C28,E5)+IF(F5="",0,F5)+IF(G5="",0,G5)+C5*차량_정보!C39) -> 113.02333 | L5: =IF(OR(C5="",H5="",I5=""),"",C5*CHOOSE(I5,0.15,0.2,0.25)*H5) -> 120 | M5: =IF(OR(J5="",K5=""),"",J5-K5) -> -63.023333 | N5: 3명 풀+1명 합류 (15·15·15·5)
K6: =IF(C6="","",IF(E6="",C6*차량_정보!C28,E6)+IF(F6="",0,F6)+IF(G6="",0,G6)+C6*차량_정보!C39) | L6: =IF(OR(C6="",H6="",I6=""),"",C6*CHOOSE(I6,0.15,0.2,0.25)*H6) | M6: =IF(OR(J6="",K6=""),"",J6-K6)
K7: =IF(C7="","",IF(E7="",C7*차량_정보!C28,E7)+IF(F7="",0,F7)+IF(G7="",0,G7)+C7*차량_정보!C39) | L7: =IF(OR(C7="",H7="",I7=""),"",C7*CHOOSE(I7,0.15,0.2,0.25)*H7) | M7: =IF(OR(J7="",K7=""),"",J7-K7)
K8: =IF(C8="","",IF(E8="",C8*차량_정보!C28,E8)+IF(F8="",0,F8)+IF(G8="",0,G8)+C8*차량_정보!C39) | L8: =IF(OR(C8="",H8="",I8=""),"",C8*CHOOSE(I8,0.15,0.2,0.25)*H8) | M8: =IF(OR(J8="",K8=""),"",J8-K8)
K9: =IF(C9="","",IF(E9="",C9*차량_정보!C28,E9)+IF(F9="",0,F9)+IF(G9="",0,G9)+C9*차량_정보!C39) | L9: =IF(OR(C9="",H9="",I9=""),"",C9*CHOOSE(I9,0.15,0.2,0.25)*H9) | M9: =IF(OR(J9="",K9=""),"",J9-K9)
K10: =IF(C10="","",IF(E10="",C10*차량_정보!C28,E10)+IF(F10="",0,F10)+IF(G10="",0,G10)+C10*차량_정보!C39) | L10: =IF(OR(C10="",H10="",I10=""),"",C10*CHOOSE(I10,0.15,0.2,0.25)*H10) | M10: =IF(OR(J10="",K10=""),"",J10-K10)
K11: =IF(C11="","",IF(E11="",C11*차량_정보!C28,E11)+IF(F11="",0,F11)+IF(G11="",0,G11)+C11*차량_정보!C39) | L11: =IF(OR(C11="",H11="",I11=""),"",C11*CHOOSE(I11,0.15,0.2,0.25)*H11) | M11: =IF(OR(J11="",K11=""),"",J11-K11)
K12: =IF(C12="","",IF(E12="",C12*차량_정보!C28,E12)+IF(F12="",0,F12)+IF(G12="",0,G12)+C12*차량_정보!C39) | L12: =IF(OR(C12="",H12="",I12=""),"",C12*CHOOSE(I12,0.15,0.2,0.25)*H12) | M12: =IF(OR(J12="",K12=""),"",J12-K12)
K13: =IF(C13="","",IF(E13="",C13*차량_정보!C28,E13)+IF(F13="",0,F13)+IF(G13="",0,G13)+C13*차량_정보!C39) | L13: =IF(OR(C13="",H13="",I13=""),"",C13*CHOOSE(I13,0.15,0.2,0.25)*H13) | M13: =IF(OR(J13="",K13=""),"",J13-K13)
K14: =IF(C14="","",IF(E14="",C14*차량_정보!C28,E14)+IF(F14="",0,F14)+IF(G14="",0,G14)+C14*차량_정보!C39) | L14: =IF(OR(C14="",H14="",I14=""),"",C14*CHOOSE(I14,0.15,0.2,0.25)*H14) | M14: =IF(OR(J14="",K14=""),"",J14-K14)
K15: =IF(C15="","",IF(E15="",C15*차량_정보!C28,E15)+IF(F15="",0,F15)+IF(G15="",0,G15)+C15*차량_정보!C39) | L15: =IF(OR(C15="",H15="",I15=""),"",C15*CHOOSE(I15,0.15,0.2,0.25)*H15) | M15: =IF(OR(J15="",K15=""),"",J15-K15)
K16: =IF(C16="","",IF(E16="",C16*차량_정보!C28,E16)+IF(F16="",0,F16)+IF(G16="",0,G16)+C16*차량_정보!C39) | L16: =IF(OR(C16="",H16="",I16=""),"",C16*CHOOSE(I16,0.15,0.2,0.25)*H16) | M16: =IF(OR(J16="",K16=""),"",J16-K16)
K17: =IF(C17="","",IF(E17="",C17*차량_정보!C28,E17)+IF(F17="",0,F17)+IF(G17="",0,G17)+C17*차량_정보!C39) | L17: =IF(OR(C17="",H17="",I17=""),"",C17*CHOOSE(I17,0.15,0.2,0.25)*H17) | M17: =IF(OR(J17="",K17=""),"",J17-K17)
K18: =IF(C18="","",IF(E18="",C18*차량_정보!C28,E18)+IF(F18="",0,F18)+IF(G18="",0,G18)+C18*차량_정보!C39) | L18: =IF(OR(C18="",H18="",I18=""),"",C18*CHOOSE(I18,0.15,0.2,0.25)*H18) | M18: =IF(OR(J18="",K18=""),"",J18-K18)
K19: =IF(C19="","",IF(E19="",C19*차량_정보!C28,E19)+IF(F19="",0,F19)+IF(G19="",0,G19)+C19*차량_정보!C39) | L19: =IF(OR(C19="",H19="",I19=""),"",C19*CHOOSE(I19,0.15,0.2,0.25)*H19) | M19: =IF(OR(J19="",K19=""),"",J19-K19)
K20: =IF(C20="","",IF(E20="",C20*차량_정보!C28,E20)+IF(F20="",0,F20)+IF(G20="",0,G20)+C20*차량_정보!C39) | L20: =IF(OR(C20="",H20="",I20=""),"",C20*CHOOSE(I20,0.15,0.2,0.25)*H20) | M20: =IF(OR(J20="",K20=""),"",J20-K20)
K21: =IF(C21="","",IF(E21="",C21*차량_정보!C28,E21)+IF(F21="",0,F21)+IF(G21="",0,G21)+C21*차량_정보!C39) | L21: =IF(OR(C21="",H21="",I21=""),"",C21*CHOOSE(I21,0.15,0.2,0.25)*H21) | M21: =IF(OR(J21="",K21=""),"",J21-K21)
K22: =IF(C22="","",IF(E22="",C22*차량_정보!C28,E22)+IF(F22="",0,F22)+IF(G22="",0,G22)+C22*차량_정보!C39) | L22: =IF(OR(C22="",H22="",I22=""),"",C22*CHOOSE(I22,0.15,0.2,0.25)*H22) | M22: =IF(OR(J22="",K22=""),"",J22-K22)
K23: =IF(C23="","",IF(E23="",C23*차량_정보!C28,E23)+IF(F23="",0,F23)+IF(G23="",0,G23)+C23*차량_정보!C39) | L23: =IF(OR(C23="",H23="",I23=""),"",C23*CHOOSE(I23,0.15,0.2,0.25)*H23) | M23: =IF(OR(J23="",K23=""),"",J23-K23)
K24: =IF(C24="","",IF(E24="",C24*차량_정보!C28,E24)+IF(F24="",0,F24)+IF(G24="",0,G24)+C24*차량_정보!C39) | L24: =IF(OR(C24="",H24="",I24=""),"",C24*CHOOSE(I24,0.15,0.2,0.25)*H24) | M24: =IF(OR(J24="",K24=""),"",J24-K24)
K25: =IF(C25="","",IF(E25="",C25*차량_정보!C28,E25)+IF(F25="",0,F25)+IF(G25="",0,G25)+C25*차량_정보!C39) | L25: =IF(OR(C25="",H25="",I25=""),"",C25*CHOOSE(I25,0.15,0.2,0.25)*H25) | M25: =IF(OR(J25="",K25=""),"",J25-K25)
K26: =IF(C26="","",IF(E26="",C26*차량_정보!C28,E26)+IF(F26="",0,F26)+IF(G26="",0,G26)+C26*차량_정보!C39) | L26: =IF(OR(C26="",H26="",I26=""),"",C26*CHOOSE(I26,0.15,0.2,0.25)*H26) | M26: =IF(OR(J26="",K26=""),"",J26-K26)
K27: =IF(C27="","",IF(E27="",C27*차량_정보!C28,E27)+IF(F27="",0,F27)+IF(G27="",0,G27)+C27*차량_정보!C39) | L27: =IF(OR(C27="",H27="",I27=""),"",C27*CHOOSE(I27,0.15,0.2,0.25)*H27) | M27: =IF(OR(J27="",K27=""),"",J27-K27)
K28: =IF(C28="","",IF(E28="",C28*차량_정보!C28,E28)+IF(F28="",0,F28)+IF(G28="",0,G28)+C28*차량_정보!C39) | L28: =IF(OR(C28="",H28="",I28=""),"",C28*CHOOSE(I28,0.15,0.2,0.25)*H28) | M28: =IF(OR(J28="",K28=""),"",J28-K28)
K29: =IF(C29="","",IF(E29="",C29*차량_정보!C28,E29)+IF(F29="",0,F29)+IF(G29="",0,G29)+C29*차량_정보!C39) | L29: =IF(OR(C29="",H29="",I29=""),"",C29*CHOOSE(I29,0.15,0.2,0.25)*H29) | M29: =IF(OR(J29="",K29=""),"",J29-K29)
K30: =IF(C30="","",IF(E30="",C30*차량_정보!C28,E30)+IF(F30="",0,F30)+IF(G30="",0,G30)+C30*차량_정보!C39) | L30: =IF(OR(C30="",H30="",I30=""),"",C30*CHOOSE(I30,0.15,0.2,0.25)*H30) | M30: =IF(OR(J30="",K30=""),"",J30-K30)
K31: =IF(C31="","",IF(E31="",C31*차량_정보!C28,E31)+IF(F31="",0,F31)+IF(G31="",0,G31)+C31*차량_정보!C39) | L31: =IF(OR(C31="",H31="",I31=""),"",C31*CHOOSE(I31,0.15,0.2,0.25)*H31) | M31: =IF(OR(J31="",K31=""),"",J31-K31)
K32: =IF(C32="","",IF(E32="",C32*차량_정보!C28,E32)+IF(F32="",0,F32)+IF(G32="",0,G32)+C32*차량_정보!C39) | L32: =IF(OR(C32="",H32="",I32=""),"",C32*CHOOSE(I32,0.15,0.2,0.25)*H32) | M32: =IF(OR(J32="",K32=""),"",J32-K32)
K33: =IF(C33="","",IF(E33="",C33*차량_정보!C28,E33)+IF(F33="",0,F33)+IF(G33="",0,G33)+C33*차량_정보!C39) | L33: =IF(OR(C33="",H33="",I33=""),"",C33*CHOOSE(I33,0.15,0.2,0.25)*H33) | M33: =IF(OR(J33="",K33=""),"",J33-K33)
K34: =IF(C34="","",IF(E34="",C34*차량_정보!C28,E34)+IF(F34="",0,F34)+IF(G34="",0,G34)+C34*차량_정보!C39) | L34: =IF(OR(C34="",H34="",I34=""),"",C34*CHOOSE(I34,0.15,0.2,0.25)*H34) | M34: =IF(OR(J34="",K34=""),"",J34-K34)
K35: =IF(C35="","",IF(E35="",C35*차량_정보!C28,E35)+IF(F35="",0,F35)+IF(G35="",0,G35)+C35*차량_정보!C39) | L35: =IF(OR(C35="",H35="",I35=""),"",C35*CHOOSE(I35,0.15,0.2,0.25)*H35) | M35: =IF(OR(J35="",K35=""),"",J35-K35)
K36: =IF(C36="","",IF(E36="",C36*차량_정보!C28,E36)+IF(F36="",0,F36)+IF(G36="",0,G36)+C36*차량_정보!C39) | L36: =IF(OR(C36="",H36="",I36=""),"",C36*CHOOSE(I36,0.15,0.2,0.25)*H36) | M36: =IF(OR(J36="",K36=""),"",J36-K36)
K37: =IF(C37="","",IF(E37="",C37*차량_정보!C28,E37)+IF(F37="",0,F37)+IF(G37="",0,G37)+C37*차량_정보!C39) | L37: =IF(OR(C37="",H37="",I37=""),"",C37*CHOOSE(I37,0.15,0.2,0.25)*H37) | M37: =IF(OR(J37="",K37=""),"",J37-K37)
K38: =IF(C38="","",IF(E38="",C38*차량_정보!C28,E38)+IF(F38="",0,F38)+IF(G38="",0,G38)+C38*차량_정보!C39) | L38: =IF(OR(C38="",H38="",I38=""),"",C38*CHOOSE(I38,0.15,0.2,0.25)*H38) | M38: =IF(OR(J38="",K38=""),"",J38-K38)
K39: =IF(C39="","",IF(E39="",C39*차량_정보!C28,E39)+IF(F39="",0,F39)+IF(G39="",0,G39)+C39*차량_정보!C39) | L39: =IF(OR(C39="",H39="",I39=""),"",C39*CHOOSE(I39,0.15,0.2,0.25)*H39) | M39: =IF(OR(J39="",K39=""),"",J39-K39)
K40: =IF(C40="","",IF(E40="",C40*차량_정보!C28,E40)+IF(F40="",0,F40)+IF(G40="",0,G40)+C40*차량_정보!C39) | L40: =IF(OR(C40="",H40="",I40=""),"",C40*CHOOSE(I40,0.15,0.2,0.25)*H40) | M40: =IF(OR(J40="",K40=""),"",J40-K40)
K41: =IF(C41="","",IF(E41="",C41*차량_정보!C28,E41)+IF(F41="",0,F41)+IF(G41="",0,G41)+C41*차량_정보!C39) | L41: =IF(OR(C41="",H41="",I41=""),"",C41*CHOOSE(I41,0.15,0.2,0.25)*H41) | M41: =IF(OR(J41="",K41=""),"",J41-K41)
...

Sheet 이동_기록
A1: 🚗 이동 기록부 — 픽업·운송·이사
A3: 👇 노란 셀에 입력 → 회색 셀은 자동 계산
A4: 일자 | B4: 서비스 종류 | C4: 구간 | D4: km (왕복) | E4: 시간(h) | F4: 연료(€) | G4: 톨(€) | H4: 받은 돈(€) | I4: 진짜 비용(€) | J4: 시간당 수익(€/h) | K4: 흑자/적자(€) | L4: 메모
I5: =IF(D5="","",IF(F5="",D5*차량_정보!C28,F5)+IF(G5="",0,G5)+D5*차량_정보!C39+IF(E5="",0,E5*차량_정보!B16)) | J5: =IF(OR(H5="",E5="",E5=0),"",H5/E5) | K5: =IF(OR(H5="",I5=""),"",H5-I5)
I6: =IF(D6="","",IF(F6="",D6*차량_정보!C28,F6)+IF(G6="",0,G6)+D6*차량_정보!C39+IF(E6="",0,E6*차량_정보!B16)) | J6: =IF(OR(H6="",E6="",E6=0),"",H6/E6) | K6: =IF(OR(H6="",I6=""),"",H6-I6)
I7: =IF(D7="","",IF(F7="",D7*차량_정보!C28,F7)+IF(G7="",0,G7)+D7*차량_정보!C39+IF(E7="",0,E7*차량_정보!B16)) | J7: =IF(OR(H7="",E7="",E7=0),"",H7/E7) | K7: =IF(OR(H7="",I7=""),"",H7-I7)
I8: =IF(D8="","",IF(F8="",D8*차량_정보!C28,F8)+IF(G8="",0,G8)+D8*차량_정보!C39+IF(E8="",0,E8*차량_정보!B16)) | J8: =IF(OR(H8="",E8="",E8=0),"",H8/E8) | K8: =IF(OR(H8="",I8=""),"",H8-I8)
I9: =IF(D9="","",IF(F9="",D9*차량_정보!C28,F9)+IF(G9="",0,G9)+D9*차량_정보!C39+IF(E9="",0,E9*차량_정보!B16)) | J9: =IF(OR(H9="",E9="",E9=0),"",H9/E9) | K9: =IF(OR(H9="",I9=""),"",H9-I9)
I10: =IF(D10="","",IF(F10="",D10*차량_정보!C28,F10)+IF(G10="",0,G10)+D10*차량_정보!C39+IF(E10="",0,E10*차량_정보!B16)) | J10: =IF(OR(H10="",E10="",E10=0),"",H10/E10) | K10: =IF(OR(H10="",I10=""),"",H10-I10)
I11: =IF(D11="","",IF(F11="",D11*차량_정보!C28,F11)+IF(G11="",0,G11)+D11*차량_정보!C39+IF(E11="",0,E11*차량_정보!B16)) | J11: =IF(OR(H11="",E11="",E11=0),"",H11/E11) | K11: =IF(OR(H11="",I11=""),"",H11-I11)
I12: =IF(D12="","",IF(F12="",D12*차량_정보!C28,F12)+IF(G12="",0,G12)+D12*차량_정보!C39+IF(E12="",0,E12*차량_정보!B16)) | J12: =IF(OR(H12="",E12="",E12=0),"",H12/E12) | K12: =IF(OR(H12="",I12=""),"",H12-I12)
I13: =IF(D13="","",IF(F13="",D13*차량_정보!C28,F13)+IF(G13="",0,G13)+D13*차량_정보!C39+IF(E13="",0,E13*차량_정보!B16)) | J13: =IF(OR(H13="",E13="",E13=0),"",H13/E13) | K13: =IF(OR(H13="",I13=""),"",H13-I13)
I14: =IF(D14="","",IF(F14="",D14*차량_정보!C28,F14)+IF(G14="",0,G14)+D14*차량_정보!C39+IF(E14="",0,E14*차량_정보!B16)) | J14: =IF(OR(H14="",E14="",E14=0),"",H14/E14) | K14: =IF(OR(H14="",I14=""),"",H14-I14)
I15: =IF(D15="","",IF(F15="",D15*차량_정보!C28,F15)+IF(G15="",0,G15)+D15*차량_정보!C39+IF(E15="",0,E15*차량_정보!B16)) | J15: =IF(OR(H15="",E15="",E15=0),"",H15/E15) | K15: =IF(OR(H15="",I15=""),"",H15-I15)
I16: =IF(D16="","",IF(F16="",D16*차량_정보!C28,F16)+IF(G16="",0,G16)+D16*차량_정보!C39+IF(E16="",0,E16*차량_정보!B16)) | J16: =IF(OR(H16="",E16="",E16=0),"",H16/E16) | K16: =IF(OR(H16="",I16=""),"",H16-I16)
I17: =IF(D17="","",IF(F17="",D17*차량_정보!C28,F17)+IF(G17="",0,G17)+D17*차량_정보!C39+IF(E17="",0,E17*차량_정보!B16)) | J17: =IF(OR(H17="",E17="",E17=0),"",H17/E17) | K17: =IF(OR(H17="",I17=""),"",H17-I17)
I18: =IF(D18="","",IF(F18="",D18*차량_정보!C28,F18)+IF(G18="",0,G18)+D18*차량_정보!C39+IF(E18="",0,E18*차량_정보!B16)) | J18: =IF(OR(H18="",E18="",E18=0),"",H18/E18) | K18: =IF(OR(H18="",I18=""),"",H18-I18)
I19: =IF(D19="","",IF(F19="",D19*차량_정보!C28,F19)+IF(G19="",0,G19)+D19*차량_정보!C39+IF(E19="",0,E19*차량_정보!B16)) | J19: =IF(OR(H19="",E19="",E19=0),"",H19/E19) | K19: =IF(OR(H19="",I19=""),"",H19-I19)
I20: =IF(D20="","",IF(F20="",D20*차량_정보!C28,F20)+IF(G20="",0,G20)+D20*차량_정보!C39+IF(E20="",0,E20*차량_정보!B16)) | J20: =IF(OR(H20="",E20="",E20=0),"",H20/E20) | K20: =IF(OR(H20="",I20=""),"",H20-I20)
I21: =IF(D21="","",IF(F21="",D21*차량_정보!C28,F21)+IF(G21="",0,G21)+D21*차량_정보!C39+IF(E21="",0,E21*차량_정보!B16)) | J21: =IF(OR(H21="",E21="",E21=0),"",H21/E21) | K21: =IF(OR(H21="",I21=""),"",H21-I21)
I22: =IF(D22="","",IF(F22="",D22*차량_정보!C28,F22)+IF(G22="",0,G22)+D22*차량_정보!C39+IF(E22="",0,E22*차량_정보!B16)) | J22: =IF(OR(H22="",E22="",E22=0),"",H22/E22) | K22: =IF(OR(H22="",I22=""),"",H22-I22)
I23: =IF(D23="","",IF(F23="",D23*차량_정보!C28,F23)+IF(G23="",0,G23)+D23*차량_정보!C39+IF(E23="",0,E23*차량_정보!B16)) | J23: =IF(OR(H23="",E23="",E23=0),"",H23/E23) | K23: =IF(OR(H23="",I23=""),"",H23-I23)
I24: =IF(D24="","",IF(F24="",D24*차량_정보!C28,F24)+IF(G24="",0,G24)+D24*차량_정보!C39+IF(E24="",0,E24*차량_정보!B16)) | J24: =IF(OR(H24="",E24="",E24=0),"",H24/E24) | K24: =IF(OR(H24="",I24=""),"",H24-I24)
I25: =IF(D25="","",IF(F25="",D25*차량_정보!C28,F25)+IF(G25="",0,G25)+D25*차량_정보!C39+IF(E25="",0,E25*차량_정보!B16)) | J25: =IF(OR(H25="",E25="",E25=0),"",H25/E25) | K25: =IF(OR(H25="",I25=""),"",H25-I25)
I26: =IF(D26="","",IF(F26="",D26*차량_정보!C28,F26)+IF(G26="",0,G26)+D26*차량_정보!C39+IF(E26="",0,E26*차량_정보!B16)) | J26: =IF(OR(H26="",E26="",E26=0),"",H26/E26) | K26: =IF(OR(H26="",I26=""),"",H26-I26)
I27: =IF(D27="","",IF(F27="",D27*차량_정보!C28,F27)+IF(G27="",0,G27)+D27*차량_정보!C39+IF(E27="",0,E27*차량_정보!B16)) | J27: =IF(OR(H27="",E27="",E27=0),"",H27/E27) | K27: =IF(OR(H27="",I27=""),"",H27-I27)
I28: =IF(D28="","",IF(F28="",D28*차량_정보!C28,F28)+IF(G28="",0,G28)+D28*차량_정보!C39+IF(E28="",0,E28*차량_정보!B16)) | J28: =IF(OR(H28="",E28="",E28=0),"",H28/E28) | K28: =IF(OR(H28="",I28=""),"",H28-I28)
I29: =IF(D29="","",IF(F29="",D29*차량_정보!C28,F29)+IF(G29="",0,G29)+D29*차량_정보!C39+IF(E29="",0,E29*차량_정보!B16)) | J29: =IF(OR(H29="",E29="",E29=0),"",H29/E29) | K29: =IF(OR(H29="",I29=""),"",H29-I29)
I30: =IF(D30="","",IF(F30="",D30*차량_정보!C28,F30)+IF(G30="",0,G30)+D30*차량_정보!C39+IF(E30="",0,E30*차량_정보!B16)) | J30: =IF(OR(H30="",E30="",E30=0),"",H30/E30) | K30: =IF(OR(H30="",I30=""),"",H30-I30)
I31: =IF(D31="","",IF(F31="",D31*차량_정보!C28,F31)+IF(G31="",0,G31)+D31*차량_정보!C39+IF(E31="",0,E31*차량_정보!B16)) | J31: =IF(OR(H31="",E31="",E31=0),"",H31/E31) | K31: =IF(OR(H31="",I31=""),"",H31-I31)
I32: =IF(D32="","",IF(F32="",D32*차량_정보!C28,F32)+IF(G32="",0,G32)+D32*차량_정보!C39+IF(E32="",0,E32*차량_정보!B16)) | J32: =IF(OR(H32="",E32="",E32=0),"",H32/E32) | K32: =IF(OR(H32="",I32=""),"",H32-I32)
I33: =IF(D33="","",IF(F33="",D33*차량_정보!C28,F33)+IF(G33="",0,G33)+D33*차량_정보!C39+IF(E33="",0,E33*차량_정보!B16)) | J33: =IF(OR(H33="",E33="",E33=0),"",H33/E33) | K33: =IF(OR(H33="",I33=""),"",H33-I33)
I34: =IF(D34="","",IF(F34="",D34*차량_정보!C28,F34)+IF(G34="",0,G34)+D34*차량_정보!C39+IF(E34="",0,E34*차량_정보!B16)) | J34: =IF(OR(H34="",E34="",E34=0),"",H34/E34) | K34: =IF(OR(H34="",I34=""),"",H34-I34)
I35: =IF(D35="","",IF(F35="",D35*차량_정보!C28,F35)+IF(G35="",0,G35)+D35*차량_정보!C39+IF(E35="",0,E35*차량_정보!B16)) | J35: =IF(OR(H35="",E35="",E35=0),"",H35/E35) | K35: =IF(OR(H35="",I35=""),"",H35-I35)
I36: =IF(D36="","",IF(F36="",D36*차량_정보!C28,F36)+IF(G36="",0,G36)+D36*차량_정보!C39+IF(E36="",0,E36*차량_정보!B16)) | J36: =IF(OR(H36="",E36="",E36=0),"",H36/E36) | K36: =IF(OR(H36="",I36=""),"",H36-I36)
I37: =IF(D37="","",IF(F37="",D37*차량_정보!C28,F37)+IF(G37="",0,G37)+D37*차량_정보!C39+IF(E37="",0,E37*차량_정보!B16)) | J37: =IF(OR(H37="",E37="",E37=0),"",H37/E37) | K37: =IF(OR(H37="",I37=""),"",H37-I37)
I38: =IF(D38="","",IF(F38="",D38*차량_정보!C28,F38)+IF(G38="",0,G38)+D38*차량_정보!C39+IF(E38="",0,E38*차량_정보!B16)) | J38: =IF(OR(H38="",E38="",E38=0),"",H38/E38) | K38: =IF(OR(H38="",I38=""),"",H38-I38)
I39: =IF(D39="","",IF(F39="",D39*차량_정보!C28,F39)+IF(G39="",0,G39)+D39*차량_정보!C39+IF(E39="",0,E39*차량_정보!B16)) | J39: =IF(OR(H39="",E39="",E39=0),"",H39/E39) | K39: =IF(OR(H39="",I39=""),"",H39-I39)
I40: =IF(D40="","",IF(F40="",D40*차량_정보!C28,F40)+IF(G40="",0,G40)+D40*차량_정보!C39+IF(E40="",0,E40*차량_정보!B16)) | J40: =IF(OR(H40="",E40="",E40=0),"",H40/E40) | K40: =IF(OR(H40="",I40=""),"",H40-I40)
I41: =IF(D41="","",IF(F41="",D41*차량_정보!C28,F41)+IF(G41="",0,G41)+D41*차량_정보!C39+IF(E41="",0,E41*차량_정보!B16)) | J41: =IF(OR(H41="",E41="",E41=0),"",H41/E41) | K41: =IF(OR(H41="",I41=""),"",H41-I41)
...

Sheet 정비_영수증
A1: 🔧 정비 영수증 누적 트래커
A3: 연 정비 충당 €2,500 + 큰수리 예비 €2,000 = 총 €4,500 잔액 추적
A4: 카테고리: "정기" (오일·타이어·소모품) | "큰수리" (터보·DPF·클러치 등)
A5: 항목 | B5: 값
A6: 연 정비 충당 예산 (€) | B6: =차량_정보!B12 -> 2500
A7: 연 큰수리 예비 예산 (€) | B7: =차량_정보!B13 -> 2000
A8: 연 총 충당 예산 (€) | B8: =B6+B7 -> 4500
A9: YTD 실제 정비 지출 (€) | B9: =SUM(D11:D200) -> 0
A10: 일자 | B10: 항목 | C10: 카테고리 | D10: 금액 (€) | E10: 주행거리 시점 | F10: 메모
A11: YTD 큰수리 지출 (€) | B11: =SUMIF(C11:C200,"큰수리",D11:D200) -> 0

Sheet 가격_계산기
A1: 🧮 가격 계산기 — 거리·인원·티어 입력
A3: 입력 (노란 셀)
A4: 거리 (km, 왕복) — 여행/픽업/이사용 | B4: 200
A5: 시간 (h, 운행 + 가이드) | B5: 8
A6: 친구 인원 (운전자 제외) | B6: 4
A7: 티어 (1=절친 / 2=친구 / 3=지인) | B7: 2
A8: 🆕 IKEA → 집 거리 (km, 편도) | B8: 12
A10: 출력 (자동 계산)
A11: 항목 | B11: 값 | C11: 메모
A12: 진짜 km당 실비 | B12: =차량_정보!C38 -> 0.60511667 | C12: 차량_정보 시트에서 자동 참조
A13: 총 진짜 비용 | B13: =B4*차량_정보!C38 -> 121.02333 | C13: km × km당 실비
A14: 마모/감가 부분 | B14: =B4*차량_정보!C39 -> 88.023333 | C14: 친구 보조금 계산용
A15: 🌿 여행 모드 1인당 (Tier 1 절친 €0.15) | B15: =B4*0.15 -> 30 | C15: 4명이면 ×4
A16: 🌿 여행 모드 1인당 (Tier 2 친구 €0.20) | B16: =B4*0.2 -> 40
A17: 🌿 여행 모드 1인당 (Tier 3 지인 €0.25) | B17: =B4*0.25 -> 50
A18: 🌿 여행 모드 그룹 합계 (선택 티어) | B18: =B4*CHOOSE(B7,0.15,0.2,0.25)*B6 -> 160 | C18: 거리 × 티어 × 인원
A19: 🚗 픽업 모드 권장가 (시내 12km 이내) | B19: =45 -> 45 | C19: 톨·1h 대기 포함
A20: 🚗 픽업 모드 권장가 (외곽, 12km 초과) | B20: =IF(B4<=12,45,45+(B4-12)*1.5) -> 327 | C20: 12km 초과분 ×€1.5
A21: 🏠 이사 모드 권장가 (시간 + km) | B21: =B5*차량_정보!B17+B4*0.5+30 -> 290 | C21: 시간 × €20 + km × €0.5 + 기본 €30
A22: 📦 시내 짐 운송 (1h, 캐리어/박스) | B22: =40 -> 40 | C22: Red Door €45 대비 −€5
A23: 🆕 📦 IKEA Tier A 권장가 (Zone 자동) | B23: =IF(B8="","",IF(B8<=10,50,IF(B8<=20,60,IF(B8<=30,75,IF(B8<=50,100,50+(B8-10)*2))))) -> 60 | C23: IKEA → 집 거리 입력 (B8)
A24: ↳ 해당 Zone | B24: =IF(B8="","",IF(B8<=10,"Zone 1 (시내, 0–10km)",IF(B8<=20,"Zone 2 (외곽, 10–20km)",IF(B8<=30,"Zone 3 (그레이터, 20–30km)",IF(B8<=50,"Zone 4 (지방, 30–50km)","Zone 5 (50km+)"))))) -> Zone 2 (외곽, 10–20km) | C24: 거리 기반 자동 분류
A25: ↳ 50km+ 시 km당 추가 | B25: =IF(B8<=50,"적용 안 함","€2/km × ("&(B8-10)&"km−10)") -> 적용 안 함 | C25: 존5 공식: €50 + (거리−10)×€2
A28: 📋 6개 행선지 빠른 참조 (4명 그룹)
A29: 행선지 | B29: km | C29: Tier 1 (절친) | D29: Tier 2 (친구) | E29: Tier 3 (지인)
A30: Wicklow | B30: 150 | C30: 22.5 | D30: 30 | E30: 37.5
A31: 골웨이/번래티 | B31: 420 | C31: 63 | D31: 84 | E31: 105
A32: 북아일랜드 (자이언트 코즈웨이) | B32: 500 | C32: 75 | D32: 100 | E32: 125
A33: 모허 (Cliffs of Moher) | B33: 540 | C33: 81 | D33: 108 | E33: 135
A34: Donegal | B34: 600 | C34: 90 | D34: 120 | E34: 150
A35: Kerry/Dingle | B35: 750 | C35: 112.5 | D35: 150 | E35: 187.5
A38: 📦 IKEA Tier A — Zone별 빠른 참조
A39: Zone | B39: IKEA → 집 거리 | C39: 대표 지역 | D39: 권장가 | E39: 메모
A40: Zone 1 | B40: 0–10 km | C40: D1–D8, D9, D15 | D40: 50 | E40: 시내 대부분
A41: Zone 2 | B41: 10–20 km | C41: D24·Tallaght·Lucan·Howth | D41: 60
A42: Zone 3 | B42: 20–30 km | C42: Maynooth·Bray·Greystones | D42: 75
A43: Zone 4 | B43: 30–50 km | C43: Drogheda·Naas·Wicklow Town | D43: 100
A44: Zone 5 | B44: 50 km + | C44: 별도 견적 | D44: €50+(거리−10)×€2 | E44: 예: 60km = €150
A46: 📦 차량 적재량 (Citroen Grand C4 Picasso 2012, 7인승 MPV):
A47: • 5인승 모드 부트 645L = IKEA 일반 쇼핑 1–2회 OK
...
